#VRML_SIM R2022b utf8

EXTERNPROTO "https://raw.githubusercontent.com/cyberbotics/webots/R2022b/projects/objects/backgrounds/protos/TexturedBackground.proto"
EXTERNPROTO "https://raw.githubusercontent.com/cyberbotics/webots/R2022b/projects/objects/backgrounds/protos/TexturedBackgroundLight.proto"
EXTERNPROTO "https://raw.githubusercontent.com/cyberbotics/webots/R2022b/projects/objects/floors/protos/CircleArena.proto"

WorldInfo {
}
Viewpoint {
  orientation -0.33185733874619844 -0.09874274160469809 0.9381474178937331 3.686018050088086
  position 1.700313773507203 1.0549607538959629 1.4846240848267684
  follow "robot"
}
TexturedBackground {
}
TexturedBackgroundLight {
}
CircleArena {
}
Robot {
  children [
    HingeJoint {
      jointParameters HingeJointParameters {
        axis 0 1 0
        anchor -0.07 0 0.025
      }
      device [
        RotationalMotor {
          name "back left leg motor"
        }
      ]
      endPoint Solid {
        translation -0.07 0.045 0
        children [
          DEF LEG Shape {
            appearance PBRAppearance {
              baseColor 1 0 0
              roughness 1
              metalness 0
            }
            geometry Box {
              size 0.01 0.01 0.045
            }
          }
        ]
        name "back left leg"
        boundingObject USE LEG
        physics Physics {
        }
      }
    }
    HingeJoint {
      jointParameters HingeJointParameters {
        axis 0 1 0
        anchor -0.07 0 0.025
      }
      device [
        RotationalMotor {
          name "back right leg motor"
        }
      ]
      endPoint Solid {
        translation -0.07 -0.045 0
        children [
          USE LEG
        ]
        name "back right leg"
        boundingObject USE LEG
        physics Physics {
        }
      }
    }
    HingeJoint {
      jointParameters HingeJointParameters {
        axis 0 1 0
        anchor 0.07 0 0.025
      }
      device [
        RotationalMotor {
          name "front left leg motor"
        }
      ]
      endPoint Solid {
        translation 0.07 0.045 0
        children [
          USE LEG
        ]
        name "front left leg"
        boundingObject USE LEG
        physics Physics {
        }
      }
    }
    HingeJoint {
      jointParameters HingeJointParameters {
        axis 0 1 0
        anchor 0.07 0 0.025
      }
      device [
        RotationalMotor {
          name "front right leg motor"
        }
      ]
      endPoint Solid {
        translation 0.07 -0.045 0
        children [
          USE LEG
        ]
        name "front right leg"
        boundingObject USE LEG
        physics Physics {
        }
      }
    }
    Transform {
      translation 0 0 0.0415
      children [
        Shape {
          appearance PBRAppearance {
            baseColor 0 0 1
            roughness 1
            metalness 0
          }
          geometry DEF BODY Box {
            size 0.2 0.09 0.045
          }
        }
      ]
    }
  ]
  boundingObject Transform {
    translation 0 0 0.09
    children [
      USE BODY
    ]
  }
  physics Physics {
  }
  controller "<extern>"
  name "robot"
}